Workbook

Sheet Overview
A1: Trancendos Master Service Matrix
A3: Real, code-verified service/route/endpoint/dependency/security/deployment inventory for the 8 real, verified components covered so far. Built from the same schema as the uploaded Infinity Services Matrix template, but every value below is checked against actual source in Trancendos/Tranc3 (commit 182b52b) — no placeholder or example data was carried over.
A5: Workbook Name | B5: Trancendos Master Service Matrix
A6: Purpose | B6: Real service/route/endpoint/dependency/security/deployment catalogue for verified anchor components
A7: Owner | B7: Andrew Porter (Trancendos)
A8: Last Updated | B8: 46219
A9: Source of Truth | B9: Verified against actual code: src/, workers/, docker-compose.production.yml, infra/traefik/, deploy/terraform/ — see Notes columns for exact file references
A10: Scope | B10: 8 components deep-verified (Services/Routes/Endpoints/Dependencies/Security/Deployment sheets): The Spark, The Digital Grid, Infinity, The Void, The Workshop, The Observatory, Traefik, health-aggregator. Plus a broad structural scan of all 94 real workers/* directories (see All Workers sheet) — out of ~90 services documented in CLAUDE.md's worker map
A11: Companion doc | B11: docs/architecture/ea-workbook/ in the Tranc3 repo — this workbook and that CSV workbook describe the same 6 anchor services plus 2 infra components; keep both in sync
A12: Honesty rule | B12: Every Status/Coverage cell reflects what the code actually does today, including known gaps and broken features — not aspirational state
A14: Live Architecture Scorecard (real counts, computed from the sheets below)
A15: Metric | B15: Value | C15: Meaning
A16: Total components | B16: =COUNTA(Services!A2:A100) | C16: Real components catalogued in this workbook
A17: Live/Active components | B17: =COUNTIF(Services!H2:H100,"Live") | C17: Status=Live in Services sheet
A18: Building/migrating components | B18: =COUNTIF(Services!H2:H100,"Building") | C18: In-flight migrations (e.g. The Void: CF Worker to self-hosted)
A19: Critical components | B19: =COUNTIF(Services!J2:J100,"Critical") | C19: CriticalityCode=CRT-001 equivalents
A20: Components missing an owner | B20: =COUNTIF(Services!G2:G100,"") | C20: Should be 0 — every real component here has a named Lead AI owner
A21: Public endpoints | B21: =COUNTIF(Endpoints!J2:J100,"Public") | C21: Endpoints with a real public IP/DNS record (see Endpoints sheet)
A22: Critical dependencies | B22: =COUNTIF(Dependencies!F2:F100,"Critical") | C22: Hard dependencies whose failure has Critical impact
A23: Known real defects (see Improvement Roadmap) | B23: =COUNTIF('Improvement Roadmap'!G2:G100,"Not started") | C23: Real, verified gaps not yet fixed — not fictional governance noise

Sheet Reference Data
A1: Field | B1: Real value / source
A2: Status Values (real, from docs/architecture/ea-workbook/README.md STS- codes) | B2: Planned, Building, Deploying, Live/Active, Deploying, Failed, Retired
A3: Environment Values (real) | B3: Local (make dev-api), Production (ENV-005, SRV-CITADEL-01 — the only real production host)
A4: Criticality Values (real, CRT- codes) | B4: CRT-001 Critical (all 8 components here are CRT-001 — no lower-criticality anchor yet catalogued)
A5: Auth Values actually implemented | B5: Bearer JWT (HTTPBearer auto_error=False, src/auth/facade.py), OAuth2 authorization_code+PKCE (Infinity only, workers/infinity-auth/router.py), none enforced for Traefik dashboard on internal network
A6: ACME/TLS (real, infra/traefik/traefik.yml) | B6: certificatesResolvers.letsencrypt.acme.tlsChallenge (TLS-ALPN-01) for external; internal mTLS TLSOption on :8443 for worker-to-worker
A7: Network (real) | B7: Docker bridge tranc3-net, subnet 172.28.0.0/16 (docker-compose.production.yml)
A8: Naming pattern actually used | B8: lowercase-hyphenated container_name / service key in docker-compose.production.yml; canonical Trancendos code-name + Tier-3 Lead AI owner per CLAUDE.md

Sheet Services
A1: Service ID | B1: Service Name | C1: Canonical Trancendos Name | D1: Description | E1: Service Type | F1: Business Domain | G1: Owner (Tier 3 Lead AI) | H1: Status | I1: Environment | J1: Criticality | K1: User Facing | L1: Internal Only | M1: Data Class | N1: Real Code Path / Port | O1: Notes
A2: SRV-001 | B2: MCP Tool Registry | C2: The Spark | D2: JSON-RPC 2.0 tool discovery/invocation over HTTP/SSE | E2: API | F2: Platform Core | G2: Norman Hawkins | H2: Live | I2: Production | J2: Critical | K2: No | L2: Yes | M2: Internal | N2: src/mcp/ — mounted on tranc3-backend :8000, routes under /mcp | O2: 60s asyncio timeout on tools/call; errors returned as JSON-RPC envelope inside HTTP 200, not 4xx; bearer JWT auth, no OAuth2 scope enforced
A3: SRV-002 | B3: Workflow Engine | C3: The Digital Grid | D3: Topological BFS DAG executor, parallel layers | E3: Backend | F3: Platform Core | G3: Tyler Towncroft | H3: Live | I3: Production | J3: Critical | K3: No | L3: Yes | M3: Internal | N3: src/workflow/, workers/workflow-engine-service/ — :8034, POST /workflows | O3: AutoScalingEnabled=TRUE (max 3) but docker compose --scale can't work yet: fixed container_name + fixed host port 8034:8034 both block it
A4: SRV-003 | B4: Identity Provider | C4: Infinity | D4: OAuth2/OIDC auth, session mgmt, MFA | E4: Auth | F4: Security | G4: The Guardian (Anchor: Orb of Orisis) | H4: Live | I4: Production | J4: Critical | K4: Yes | L4: No | M4: Restricted | N4: workers/infinity-auth/ — :8005, POST /auth/token, GET /auth/verify | O4: authorization_code (+PKCE) works; refresh_token grant is broken (queries nonexistent refresh_tokens table); token_endpoint issues an opaque secrets.token_urlsafe(32) string, not a JWT, so it fails /auth/verify too
A5: SRV-004 | B5: Secrets Vault | C5: The Void | D5: AES-GCM encrypted secrets store, Shamir unseal | E5: Utility | F5: Security | G5: Prometheus | H5: Building | I5: Production | J5: Critical | K5: No | L5: Yes | M5: Restricted | N5: workers/vault-service/ — :8038, GET /secrets/{id} | O5: In-flight migration from CF Worker infinity-void; GET /secrets/{id} returns metadata only (key/tags/ttl/version), never the decrypted value — no endpoint currently exposes it
A6: SRV-005 | B6: Git Hosting & CI/CD | C6: The Workshop | D6: Self-hosted Forgejo git + Actions runner | E6: Utility | F6: DevOps | G6: Larry Lowhammer | H6: Live | I6: Production | J6: Critical | K6: Yes | L6: No | M6: Internal | N6: deploy/forgejo/ — Forgejo container :3000 (Traefik), SSH :2222 | O6: Real Traefik rule Host(trancendos.com)&&PathPrefix(/the-workshop); the-workshop.trancendos.com CNAME (real DNS record) has no matching host rule so it does not currently reach Forgejo
A7: SRV-006 | B7: Audit & Monitoring | C7: The Observatory | D7: Metrics, tracing, audit log aggregation | E7: Backend | F7: Platform Core | G7: Norman Hawkins | H7: Live | I7: Production | J7: Critical | K7: No | L7: Yes | M7: Restricted | N7: workers/observatory/ — :8065, GET /logs, /health | O7: No real persistence: OBSERVATORY_DB_PATH is mounted but never opened; audit events live only in an in-process deque (src/observability/observatory.py) and are lost on restart
A8: SRV-007 | B8: Reverse Proxy / Ingress | C8: Traefik | D8: TLS termination, routing, internal mTLS, ACME | E8: Router | F8: Infrastructure | G8: Cornelius MacIntyre | H8: Live | I8: Production | J8: Critical | K8: Yes | L8: No | M8: Public | N8: docker-compose.production.yml (tranc3-traefik) + infra/traefik/traefik.yml — :80/:443/:8443(mTLS)/:8090(ping) | O8: certResolver=letsencrypt uses tlsChallenge (TLS-ALPN-01); --ping=true fixed this session so the compose healthcheck (traefik healthcheck --ping) actually passes
A9: SRV-008 | B9: Health Aggregator | C9: health-aggregator | D9: Polls every registered service /health every 30s | E9: Utility | F9: Platform Core | G9: Cornelius MacIntyre | H9: Live | I9: Production | J9: Medium | K9: No | L9: Yes | M9: Internal | N9: workers/health-aggregator/ — :8029, POST/GET /services | O9: Hardcoded SERVICE_REGISTRY had 11 P3-block services on wrong ports (alphabetical vs real compose mapping) — fixed this session; scripts/register_ea_workbook_services.py can feed it from the CMDB but nothing calls that script automatically yet

Sheet Routes
A1: Rule ID | B1: Source | C1: Target Service | D1: Request Type | E1: Protocol | F1: Port(s) | G1: Trust Level | H1: Route Action | I1: Real Traefik Rule / Path | J1: Notes
A2: RTE-001 | B2: External Client | C2: Traefik | D2: HTTPS request | E2: HTTPS | F2: 443 | G2: Untrusted | H2: Proxy | I2: entrypoints.websecure, tls.certResolver=letsencrypt | J2: Public internet entrypoint; HTTP :80 redirects to HTTPS per infra/traefik/traefik.yml
A3: RTE-002 | B3: Traefik | C3: The Spark | D3: HTTP (internal) | E3: HTTP | F3: 8000 | G3: Internal | H3: Allow | I3: Mounted on tranc3-backend, no dedicated Traefik router label found for :8000 in compose | J3: The Spark is reached as part of the main backend app, not a standalone Traefik-routed service
A4: RTE-003 | B4: Traefik | C4: The Digital Grid | D4: HTTP (internal) | E4: HTTP | F4: 8034 | G4: Internal | H4: Allow | I4: workflow-engine-service, published host port 8034:8034 | J4: Fixed host port blocks any future scale-out beyond 1 replica
A5: RTE-004 | B5: Traefik | C5: Infinity | D5: HTTP (internal) | E5: HTTP | F5: 8005 | G5: Internal | H5: Allow | I5: infinity-auth container | J5: authorization_code + PKCE only; no /oauth2/token, no client_credentials
A6: RTE-005 | B6: Traefik | C6: The Void | D6: HTTP (internal) | E6: HTTP | F6: 8038 | G6: Internal | H6: Allow | I6: vault-service container | J6: Internal hop is plain HTTP — no TLS/mTLS configured for this in-cluster call today
A7: RTE-006 | B7: Traefik | C7: The Workshop | D7: HTTP (internal) | E7: HTTPS | F7: 3000 | G7: Internal | H7: Allow | I7: Host(`trancendos.com`) && PathPrefix(`/the-workshop`), tls.certresolver=letsencrypt | J7: Only matches Host=trancendos.com — a request with Host=the-workshop.trancendos.com does NOT match this rule
A8: RTE-007 | B8: Traefik | C8: The Observatory | D8: HTTP (internal) | E8: HTTP | F8: 8065 | G8: Internal | H8: Allow | I8: observatory container, OBSERVATORY_PORT env (fixed this session) | J8: Dockerfile CMD/HEALTHCHECK previously hardcoded 8040, ignoring compose's OBSERVATORY_PORT=8065 — fixed
A9: RTE-008 | B9: health-aggregator | C9: All 6 anchor services | D9: HTTP GET /health | E9: HTTP | F9: varies | G9: Internal | H9: Allow | I9: SERVICE_REGISTRY in workers/health-aggregator/worker.py | J9: Polls every 30s; port mapping for the P3 block was wrong for 11 services, fixed this session
A10: RTE-009 | B10: Worker-to-worker (any) | C10: Any internal worker | D10: mTLS | E10: HTTPS | F10: 8443 | G10: Internal (mTLS) | H10: Allow | I10: entryPoints.internal in infra/traefik/traefik.yml, TLSOption requires client cert signed by internal-ca.pem | J10: Separate internal-only entrypoint from the public :443 — not exposed externally

Sheet Endpoints
A1: Endpoint ID | B1: Service Name | C1: Hostname / DNS record | D1: Port | E1: Protocol | F1: Interface Type | G1: TLS | H1: Certificate Source | I1: Public Exposure? | J1: Notes
A2: EP-001 | B2: Traefik (apex) | C2: trancendos.com (A, cloudflare_record.apex) | D2: 443 | E2: HTTPS | F2: Public | G2: Yes | H2: Let's Encrypt via tlsChallenge | I2: Public | J2: Real Terraform record (deploy/terraform/oci-citadel-dns.tf); resolves to oci_core_public_ip.citadel.ip_address at apply time; proxied=false (grey cloud, required for TLS-ALPN-01)
A3: EP-002 | B3: Traefik (www) | C3: www.trancendos.com (A, cloudflare_record.www) | D3: 443 | E3: HTTPS | F3: Public | G3: Yes | H3: Let's Encrypt via tlsChallenge | I3: Public | J3: Real Terraform record; proxied=false
A4: EP-003 | B4: Traefik (api) | C4: api.trancendos.com (A, cloudflare_record.api) | D4: 443 | E4: HTTPS | F4: Public | G4: Yes | H4: Let's Encrypt via tlsChallenge | I4: Public | J4: A record inside the trancendos.com zone — NOT a separate delegated zone; proxied=false
A5: EP-004 | B5: The Workshop / Forgejo | C5: the-workshop.trancendos.com (CNAME, cloudflare_record.the_workshop) | D5: n/a | E5: HTTP(S) | F5: Public (DNS only) | G5: n/a | H5: n/a | I5: Public DNS, non-functional at HTTP layer | J5: Real DNS record provisioned by Terraform, but no Traefik host rule matches this Host header today — request does not currently reach Forgejo
A6: EP-005 | B6: The Workshop / Forgejo (SSH) | C6: trancendos.com | D6: 2222 | E6: SSH | F6: Public | G6: n/a | H6: n/a | I6: Public | J6: git+ssh clone; published as 2222:22 on the Forgejo container itself, not a separate runner node
A7: EP-006 | B7: Traefik dashboard | C7: traefik.trancendos.local | D7: 8888 | E7: HTTP | F7: Internal | G7: No | H7: None | I7: Internal | J7: Local-only Host rule (.local); also published on host port 8888 — not intended for public exposure
A8: EP-007 | B8: Internal mTLS entrypoint | C8: (container network only) | D8: 8443 | E8: HTTPS (mTLS) | F8: Internal | G8: Yes | H8: Internal CA (infra/traefik/certs/internal-ca.pem) | I8: Internal only | J8: Worker-to-worker calls requiring a client cert signed by the internal CA
A9: EP-008 | B9: Traefik ping | C9: (container network only) | D9: 8090 | E9: HTTP | F9: Internal | G9: No | H9: n/a | I9: Internal only | J9: ping.entryPoint per infra/traefik/traefik.yml; compose healthcheck instead uses --ping CLI probe on the default entrypoint

Sheet Dependencies
A1: Dependency ID | B1: Service | C1: Depends On | D1: Dependency Type | E1: Required | F1: Failure Impact | G1: Recovery Strategy (real) | H1: Notes
A2: DEP-001 | B2: The Spark | C2: The Void | D2: Secrets | E2: Yes | F2: Critical | G2: None automated — restart after Void recovers | H2: Cannot resolve secrets needed for tool execution if Void is down
A3: DEP-002 | B3: The Spark | C3: Infinity | D3: Auth | E3: Yes | F3: Critical | G3: None automated | H3: get_current_user dependency requires Infinity-issued JWTs to validate
A4: DEP-003 | B4: The Digital Grid | C4: The Void | D4: Secrets | E4: Yes | F4: Critical | G4: None automated
A5: DEP-004 | B5: The Digital Grid | C5: Infinity | D5: Auth | E5: Yes | F5: Critical | G5: None automated
A6: DEP-005 | B6: The Digital Grid | C6: The Spark | D6: Tool invocation | E6: No (soft) | F6: Medium | G6: Workflow steps that call MCP tools degrade gracefully | H6: Only workflows with MCP tool steps are affected
A7: DEP-006 | B7: Infinity | C7: The Void | D7: Secrets | E7: Yes | F7: Critical | G7: None automated | H7: Infinity cannot sign tokens if it can't reach the vault for its signing secret
A8: DEP-007 | B8: The Void | C8: Infinity | D8: Identity verification | E8: Yes | F8: Critical | G8: None automated | H8: Caller identity verification before secret release
A9: DEP-008 | B9: The Workshop | C9: Infinity | D9: Auth | E9: Yes | F9: High | G9: None automated
A10: DEP-009 | B10: The Workshop | C10: The Void | D10: Secrets | E10: Yes | F10: High | G10: None automated
A11: DEP-010 | B11: The Observatory | C11: Infinity | D11: Auth | E11: Yes | F11: Critical | G11: None automated
A12: DEP-011 | B12: The Observatory | C12: (no real DB dependency) | D12: n/a | E12: No | F12: n/a | G12: n/a | H12: 10_databases.csv DB-OBS-001 was previously listed as a hard dependency — corrected this session: the worker never opens OBSERVATORY_DB_PATH, so it cannot cause a real failure
A13: DEP-012 | B13: health-aggregator | C13: All 6 anchor services | D13: Health polling | E13: No | F13: Low | G13: Marks a service unhealthy in its own DB; does not trigger automated remediation | H13: Read-only dependency — a target being down doesn't break health-aggregator itself

Sheet Security
A1: Service Name | B1: Data Classification | C1: Authentication (real) | D1: Authorization (real) | E1: Encryption in Transit | F1: Encryption at Rest | G1: Audit Logging | H1: Notes
A2: The Spark | B2: Internal | C2: Bearer JWT via Depends(get_current_user), auto_error=False so 401 (not 403) on missing/invalid creds | D2: No OAuth2 scope declared or enforced despite security scheme listing scopes | E2: Internal HTTP only (no TLS on the tranc3-backend hop) | F2: N/A (no persistent store) | G2: Via Observatory audit middleware | H2: src/auth/facade.py:get_current_user_dep raises 401 uniformly for missing and invalid tokens
A3: The Digital Grid | B3: Internal | C3: Bearer JWT (same facade) | D3: internal-auth only via require_internal_auth | E3: Internal HTTP only | F3: SQLite file, not encrypted at rest | G3: Via Observatory audit middleware
A4: Infinity | B4: Restricted | C4: OIDC-style authorization_code+PKCE (workers/infinity-auth); refresh_token grant broken (missing table) | D4: Own JWT issuance/verification; get_current_user requires JWT | E4: External: Traefik TLS (tlsChallenge/TLS-ALPN-01); internal hop plain HTTP | F4: SQLite file, path/volume-mount mismatch means data isn't durably backed up | G4: Via Observatory audit middleware | H4: authorization_code token is opaque (secrets.token_urlsafe(32)), NOT a JWT — /auth/verify and every other protected route on this service will reject it with 401
A5: The Void | B5: Restricted | C5: internal-auth only | D5: Caller identity check against Infinity before secret release | E5: Internal hop is plain HTTP — no TLS/mTLS configured for this specific in-cluster call | F5: AES-GCM encrypted values; Shamir-split unseal keys, never stored alongside the encrypted DB | G5: Via Observatory audit middleware | H5: GET /secrets/{id} returns metadata only — no endpoint currently returns the decrypted value
A6: The Workshop | B6: Internal | C6: Forgejo's own auth (registration disabled, sign-in required to view) | D6: Forgejo RBAC | E6: External: Traefik TLS (tlsChallenge) | F6: SQLite (Forgejo's own gitea.db) | G6: Forgejo's own audit/activity log | H6: SSH clone bypasses HTTP auth entirely — key-based, published at host port 2222
A7: The Observatory | B7: Restricted | C7: Bearer JWT (same facade) for query endpoints | D7: internal-auth | E7: Internal HTTP only | F7: None — in-memory deque only, lost on restart | G7: Self-referential — Observatory IS the audit log, but not durably | H7: OBSERVATORY_DB_PATH configured but never opened; treat any retention/compliance claim about this data surviving a restart as aspirational
A8: Traefik | B8: Public-facing | C8: None for the ingress itself; per-router labels | D8: N/A (routing layer) | E8: External TLS via tlsChallenge; internal mTLS TLSOption on :8443 requiring client certs signed by internal-ca.pem | F8: N/A | G8: accessLog.format=json with header allowlist (X-Request-ID, X-Forwarded-For, X-Device-Posture kept) | H8: Dashboard (api.dashboard) enabled but insecure=false and only reachable via a .local Host rule — not exposed publicly by design
A9: health-aggregator | B9: Internal | C9: X-Internal-Secret header (INTERNAL_SECRET env, optional) | D9: n/a | E9: Internal HTTP only | F9: SQLite (health check history) | G9: Own SQLite history, not routed through Observatory | H9: If INTERNAL_SECRET is unset, /services management endpoints are unauthenticated on the internal network

Sheet Deployment
A1: Service Name | B1: Real Code Path | C1: Runtime | D1: Deployment Method (real) | E1: Rollback Method (real) | F1: Health Check | G1: Last Verified Commit (this session) | H1: Notes
A2: The Spark | B2: src/mcp/ | C2: Python 3.11 / FastAPI 0.136.3 | D2: Part of tranc3-backend — Fly.io (legacy) or manual docker compose | E2: git checkout <sha> + docker compose up -d --build (manual, no automation) | F2: /mcp/health | G2: 93d87d3e (2026-06-30) | H2: No dedicated CI artifact/pipeline run tracked yet for this path — 06_service_deployments.csv leaves those columns blank rather than fabricated
A3: The Digital Grid | B3: src/workflow/, workers/workflow-engine-service/ | C3: Python 3.11 / FastAPI 0.136.3 | D3: Manual docker compose up -d --build | E3: Same manual pattern | F3: /health | G3: df4ed5e5 (2026-06-25)
A4: Infinity | B4: workers/infinity-auth/ | C4: Python 3.11 / FastAPI 0.136.3 | D4: Manual docker compose up -d --build | E4: Same manual pattern | F4: /health | G4: a3df9128 (2026-07-12)
A5: The Void | B5: workers/vault-service/ | C5: Python 3.11 / FastAPI 0.136.3 | D5: Manual docker compose up -d --build (in-flight CF Worker migration) | E5: Same manual pattern | F5: /health | G5: d06f3b13 (2026-06-29) | H5: Migrating from cloudflare/infinity-void/
A6: The Workshop | B6: deploy/forgejo/ | C6: Forgejo (Go), image codeberg.org/forgejo/forgejo:7 | D6: deploy/forgejo/setup.sh + docker compose | E6: deploy/forgejo/recover.sh (topology-aware, real dedicated runbook) | F6: wget http://localhost:3000/-/health | G6: 8fbc80b8 (2026-07-12) | H6: The only anchor service with a genuinely dedicated recovery runbook (deploy/forgejo/RUNBOOK.md)
A7: The Observatory | B7: workers/observatory/ | C7: Python 3.11 / FastAPI 0.136.3 | D7: Manual docker compose up -d --build | E7: Same manual pattern | F7: /health | G7: d06f3b13 (2026-06-29) | H7: Dockerfile CMD/HEALTHCHECK fixed this session to honor OBSERVATORY_PORT instead of hardcoding 8040
A8: Traefik | B8: docker-compose.production.yml, infra/traefik/traefik.yml | C8: traefik:v3.0 image | D8: docker compose (part of core infra stack) | E8: docker compose restart traefik / redeploy image tag | F8: traefik healthcheck --ping (CLI probe, not an HTTP path) | G8: --ping=true added this session (182b52b lineage) | H8: Compose healthcheck was silently failing before this fix — --ping was never enabled
A9: health-aggregator | B9: workers/health-aggregator/ | C9: Python 3.11 / FastAPI 0.136.3 | D9: Manual docker compose up -d --build | E9: Same manual pattern | F9: /health | G9: 0673555 (2026-07-16, this session) | H9: SERVICE_REGISTRY port fix and scripts/post_deploy_verify.py fix landed together

Sheet Change Log
A1: Change ID | B1: Date (UTC) | C1: Commit | D1: Summary | E1: Real Impact
A2: CHG-001 | B2: 2026-07-16T18:29:43 | C2: 5c18133 | D2: Fixed remaining CMDB/docs bugs found in cubic-dev-ai review batch | E2: Corrected API routes, engine types, network subnet, Forgejo SSH port, Traefik health mechanism across the EA workbook
A3: CHG-002 | B3: 2026-07-16T18:43:35 | C3: 7b346f5 | D3: Fixed the real Traefik ping bug + 15 more CMDB findings | E3: Added --ping=true to Traefik's command args — the compose healthcheck was permanently failing before this
A4: CHG-003 | B4: 2026-07-16T18:53:04 | C4: 01efe9e | D4: Fixed health-aggregator port drift; wired EA workbook into the live system | E4: Corrected 11 P3-block services on wrong ports in health-aggregator's SERVICE_REGISTRY; added CI/pre-commit CSV validation; added register_ea_workbook_services.py
A5: CHG-004 | B5: 2026-07-16T18:57:24 | C5: e9891aa | D5: Fixed deployment chronology | E5: 6 anchor deployment rows had DeploymentDate before their own commit's real timestamp — corrected using git show
A6: CHG-005 | B6: 2026-07-16T19:13:17 | C6: 0673555 | D6: Fixed real DNS gap + second port-drift bug + script robustness | E6: Found the identical port-mapping bug duplicated in scripts/post_deploy_verify.py; found the workbook was missing 2 of 4 real Terraform-provisioned DNS records
A7: CHG-006 | B7: 2026-07-16T23:52:20 | C7: 182b52b | D7: Fixed ACME challenge type + the-workshop CNAME routing claim | E7: Corrected HTTP-01 to the real tlsChallenge/TLS-ALPN-01; discovered the-workshop CNAME has no matching Traefik host rule

Sheet Deprecations
A1: Service Name | B1: Replaced By | C1: Reason | D1: Data Migration Done | E1: Notes
A2: infinity-void (Cloudflare Worker) | B2: The Void / vault-service (self-hosted) | C2: Zero-cost self-hosted architecture migration (CLAUDE.md) | D2: In Progress | E2: cloudflare/infinity-void/ still exists in-repo as the legacy source; workers/vault-service/ is the real self-hosted replacement, StatusCode=Building
A3: tranc3-api-gateway (Cloudflare Worker) | B3: Traefik (self-hosted) | C3: Same zero-cost migration | D3: In Progress | E3: cloudflare/trancendos-api-gateway/ still exists; api.trancendos.com now routes through Traefik per Terraform

Sheet Executive Dashboard
A1: Executive Dashboard — Trancendos Master Service Matrix
A3: Component Status Summary | D3: Dependencies by Failure Impact
A4: Status | B4: Count | D4: Impact | E4: Count
A5: Live | B5: =COUNTIF(Services!H2:H100,"Live") | D5: Critical | E5: =COUNTIF(Dependencies!F2:F100,"Critical")
A6: Building | B6: =COUNTIF(Services!H2:H100,"Building") | D6: High | E6: =COUNTIF(Dependencies!F2:F100,"High")
A7: Deploying | B7: =COUNTIF(Services!H2:H100,"Deploying") | D7: Medium | E7: =COUNTIF(Dependencies!F2:F100,"Medium")
A8: Planned | B8: =COUNTIF(Services!H2:H100,"Planned") | D8: Low | E8: =COUNTIF(Dependencies!F2:F100,"Low")
A9: Failed | B9: =COUNTIF(Services!H2:H100,"Failed")
A10: Retired | B10: =COUNTIF(Services!H2:H100,"Retired")
A12: Executive Action Summary (real, from Improvement Roadmap)
A13: Metric | B13: Value | C13: Interpretation
A14: Real open defects (P1) | B14: =COUNTIFS('Improvement Roadmap'!F2:F100,"P1",'Improvement Roadmap'!G2:G100,"Not started") | C14: Highest-priority real gaps — fix before claiming full production readiness
A15: Real open defects (P2) | B15: =COUNTIFS('Improvement Roadmap'!F2:F100,"P2",'Improvement Roadmap'!G2:G100,"Not started") | C15: Should be scheduled but not urgent
A16: Components covered | B16: =COUNTA(Services!A2:A100) | C16: Out of ~90 real services documented in CLAUDE.md's worker map
A17: Deployment automation gap | B17: =COUNTIF('Improvement Roadmap'!A2:A100,"Automation") | C17: Manual docker compose deploys remain the norm — see Deployment sheet

Sheet All Workers (Broad Scan)
A1: All Workers — Broad Structural Scan (not deep-verified like the 8 anchors above)
A2: Mechanically checked against real files: presence of worker.py/Dockerfile, registration in docker-compose.production.yml, real routed port there, and whether a /health string appears in the source. This is a structural first pass across all real workers/* directories — treat rows here as a starting point for the same deep-verification the 8 anchor components received, not as equivalent confidence.
A4: Worker Directory | B4: Has worker.py | C4: Has Dockerfile | D4: In docker-compose.production.yml | E4: Real Compose Port | F4: Has /health Reference
A5: analytics-service | B5: TRUE | C5: TRUE | D5: TRUE | F5: TRUE
A6: api-gateway | B6: TRUE | C6: TRUE | D6: TRUE | E6: 8003 | F6: TRUE
A7: artifactory-service | B7: TRUE | C7: TRUE | D7: TRUE | E7: 8047 | F7: TRUE
A8: audit-service | B8: TRUE | C8: TRUE | D8: TRUE | F8: TRUE
A9: backup-service | B9: TRUE | C9: TRUE | D9: TRUE | E9: 8078 | F9: TRUE
A10: basement | B10: TRUE | C10: TRUE | D10: TRUE | E10: 8068 | F10: TRUE
A11: blender-worker | B11: TRUE | C11: TRUE | D11: TRUE | E11: 8050 | F11: TRUE
A12: bullmq-queue-service | B12: FALSE | C12: TRUE | D12: TRUE | E12: 8092 | F12: FALSE
A13: cache-service | B13: TRUE | C13: TRUE | D13: TRUE | F13: TRUE
A14: cdn-service | B14: TRUE | C14: TRUE | D14: TRUE | F14: TRUE
A15: chaos-party | B15: TRUE | C15: TRUE | D15: TRUE | E15: 8079 | F15: TRUE
A16: config-service | B16: TRUE | C16: TRUE | D16: TRUE | F16: TRUE
A17: cranbania | B17: FALSE | C17: FALSE | D17: TRUE | E17: 8071 | F17: FALSE
A18: cron-service | B18: TRUE | C18: TRUE | D18: TRUE | F18: TRUE
A19: cryptex | B19: TRUE | C19: TRUE | D19: TRUE | F19: FALSE
A20: deepagents-orchestrator-service | B20: TRUE | C20: TRUE | D20: TRUE | E20: 8037 | F20: TRUE
A21: devocity | B21: TRUE | C21: TRUE | D21: TRUE | E21: 8110 | F21: TRUE
A22: dimensional-nexus-service | B22: TRUE | C22: TRUE | D22: FALSE | F22: TRUE
A23: dspy-service | B23: TRUE | C23: TRUE | D23: TRUE | E23: 8098 | F23: TRUE
A24: email-service | B24: TRUE | C24: TRUE | D24: TRUE | F24: TRUE
A25: fabulousa-service | B25: TRUE | C25: TRUE | D25: TRUE | E25: 8048 | F25: TRUE
A26: ffmpeg-worker | B26: TRUE | C26: TRUE | D26: TRUE | E26: 8052 | F26: TRUE
A27: files-service | B27: TRUE | C27: TRUE | D27: TRUE | E27: 8014 | F27: TRUE
A28: gateway-service | B28: TRUE | C28: TRUE | D28: FALSE | F28: FALSE
A29: gbrain-bridge | B29: TRUE | C29: TRUE | D29: TRUE | F29: TRUE
A30: geo-service | B30: TRUE | C30: TRUE | D30: TRUE | F30: TRUE
A31: haystack-service | B31: TRUE | C31: TRUE | D31: TRUE | E31: 8097 | F31: TRUE
A32: health-aggregator | B32: TRUE | C32: TRUE | D32: TRUE | F32: TRUE
A33: hive-service | B33: TRUE | C33: TRUE | D33: TRUE | E33: 8051 | F33: TRUE
A34: ice-box-service | B34: TRUE | C34: TRUE | D34: TRUE | E34: 8046 | F34: TRUE
A35: identity-service | B35: TRUE | C35: TRUE | D35: TRUE | E35: 8015 | F35: TRUE
A36: imaginarium | B36: TRUE | C36: TRUE | D36: TRUE | E36: 8064 | F36: TRUE
A37: imind | B37: TRUE | C37: TRUE | D37: TRUE | E37: 8075 | F37: TRUE
A38: infinity-admin-service | B38: TRUE | C38: TRUE | D38: FALSE | F38: FALSE
A39: infinity-ai | B39: TRUE | C39: TRUE | D39: TRUE | E39: 8009 | F39: FALSE
A40: infinity-auth | B40: TRUE | C40: TRUE | D40: TRUE | E40: 8005 | F40: FALSE
A41: infinity-bridge-service | B41: TRUE | C41: TRUE | D41: FALSE | F41: TRUE
...

Sheet Improvement Roadmap
A1: Theme | B1: Action | C1: Why it matters | D1: How to complete | E1: Owner | F1: Priority | G1: Status
A2: Routing | B2: Add a Traefik host rule for the-workshop.trancendos.com | C2: Real DNS CNAME is provisioned by Terraform but was unreachable — Forgejo's only rule required Host=trancendos.com | D2: Added a redirect router (forgejo-subdomain, Host(`the-workshop.trancendos.com`)) that 301s to the canonical https://trancendos.com/the-workshop/ path — Forgejo's ROOT_URL is path-based, so serving it directly at the bare subdomain would have conflicted with its own generated links | E2: Larry Lowhammer | F2: P1 | G2: Fixed
A3: Auth | B3: Fix or replace Infinity's authorization_code token contract | C3: The issued opaque token cannot be validated by any of this service's own protected routes (/auth/verify, /auth/me) — a real, functional gap, not a doc error | D3: Either issue a signed JWT from the authorization_code grant too, or add a dedicated validation path for opaque tokens | E3: The Guardian (Anchor: Orb of Orisis) | F3: P1 | G3: Not started
A4: Auth | B4: Fix Infinity's refresh_token grant | C4: The refresh path queries a refresh_tokens table that is never created — refresh currently always fails | D4: Create the missing table/migration, or remove refresh_token support from the advertised grant types until it's implemented | E4: The Guardian (Anchor: Orb of Orisis) | F4: P1 | G4: Not started
A5: Observability | B5: Give The Observatory real persistence | C5: OBSERVATORY_DB_PATH is configured but never opened; all audit/metric data lives only in an in-process deque and is lost on every restart | D5: Wire the configured DB path into an actual SQLite writer in workers/observatory/service.py | E5: Norman Hawkins | F5: P1 | G5: Not started
A6: Automation | B6: Wire scripts/register_ea_workbook_services.py and scripts/post_deploy_verify.py into a real deploy step | C6: Both scripts exist and work (verified this session) but nothing in .forgejo/workflows/ calls either one — the CMDB doesn't drive live monitoring yet | D6: Added a verify-and-register-self-hosted job to deploy-self-hosted.yml that runs both scripts (--soft / continue-on-error, since the underlying Compose deploy step below still doesn't exist) | E6: Cornelius MacIntyre | F6: P2 | G6: Fixed
A7: Automation | B7: Make deploy-self-hosted.yml actually deploy workers/* via Docker Compose | C7: It triggers on workers/** changes but only runs flyctl for trancendos-backend/trancendos-bots — no docker compose up step exists for the self-hosted workers | D7: Add a real Compose deploy step (or document the manual host-level step explicitly as the real process) | E7: Cornelius MacIntyre | F7: P2 | G7: Not started
A8: Scaling | B8: Fix The Digital Grid's autoscaling | C8: AutoScalingEnabled=TRUE (max 3) but both the fixed container_name and the fixed 8034:8034 host port publish block more than one replica today | D8: Remove the fixed container_name and route traffic to replicas via Traefik service discovery instead of the published host port | E8: Tyler Towncroft | F8: P2 | G8: Not started
A9: Coverage | B9: Expand this matrix beyond the 8 deep-verified components | C9: CLAUDE.md documents ~90 real services; this workbook and the EA CSV workbook both cover only 6 anchors + 2 infra components at full verification depth | D9: Add one verified row per additional service across all sheets here, following the same code-verification standard used for the anchors — the All Workers (Broad Scan) sheet is a structural first pass, not a substitute for that depth | E9: Andrew Porter | F9: P3 | G9: In progress
A10: Architecture | B10: Resolve the duplicate 'Void' implementation | C10: workers/the-void/ (289 lines, includes a Rust crypto extension, last touched in commit 634962c) implements the same AES-GCM vault concept as workers/vault-service/ (803 lines, the one actually wired into docker-compose.production.yml and documented throughout this workbook) — but the-void/ is not registered in compose at all and is not deployed anywhere | D10: A human needs to decide: is the-void/ an abandoned earlier attempt safe to remove, or a newer implementation meant to eventually replace vault-service/? Do not delete either without that decision | E10: Prometheus | F10: P2 | G10: Not started
A11: Governance | B11: Merge PR #221 | C11: This entire matrix, the EA CSV workbook, and all the real bugfixes found this session live on an open, unmerged PR | D11: Get CI green and merge claude/platform-context-review-ieg1rn to main | E11: Andrew Porter | F11: P2 | G11: Not started

Sheet Governance Checks
A1: Governance Checks (live formulas — recalculate in Excel/LibreOffice)
A3: Check | B3: Live Formula | C3: Current Result | D3: Pass Target
A4: Every component has a named owner | B4: =COUNTIF(Services!G2:G100,"") | D4: 0
A5: Every component has a Security row | B5: =COUNTA(Security!A2:A100)-COUNTA(Services!A2:A100) | D5: 0
A6: Every component has a Deployment row | B6: =COUNTA(Deployment!A2:A100)-COUNTA(Services!A2:A100) | D6: 0
A7: Critical dependencies have a recovery strategy filled in | B7: =COUNTIFS(Dependencies!F2:F100,"Critical",Dependencies!G2:G100,"") | D7: 0
A8: P1 real defects still open | B8: =COUNTIFS('Improvement Roadmap'!F2:F100,"P1",'Improvement Roadmap'!G2:G100,"Not started") | D8: 0
A9: Public endpoints without TLS | B9: =COUNTIFS(Endpoints!I2:I100,"Public",Endpoints!G2:G100,"No") | D9: 0
